<mujoco>
   <default>
      <joint damping=".1" actuatorfrcrange="-0.5 0.5"/>
   </default>
   <option gravity="0 0 0" />
   <worldbody>
      <light diffuse=".5 .5 .5" pos="0 0 10" dir="0 0 -1"/>
      <geom type="plane" size="2 2 0.1" rgba="1 1 1 1"/>
      <body pos="0.5 0 0.1" euler="0 90 0">
         <joint name="t1" type="hinge" axis="-1 0 0" pos="0 0 -0.5"/>
         <geom type="cylinder" size="0.05 0.5" rgba="1 0 0 1"/>
         <body pos="0 0 1" euler="0 0 0">
            <joint name="t2" type="hinge" axis="-1 0 0" pos="0 0 -0.5"/>
            <geom type="cylinder" size="0.05 0.5" rgba="0 1 0 1"/>
            <site name="tip" size="0.1" pos="0 0 0.5"/>
         </body>
      </body>
   </worldbody>
   <sensor>
      <framepos objtype="site" objname="tip"/>
   </sensor>
   <actuator>
      <velocity name="theta_1" joint="t1"/>
      <velocity name="theta_2" joint="t2"/>
   </actuator>
</mujoco>
