<mujoco>

   <default>
      <joint damping="1"/>
      <motor ctrlrange="-3 3"/>
   </default>

   <option timestep="0.01" gravity="0 0 0" />
   <worldbody>
      <light diffuse=".5 .5 .5" pos="0 0 10" dir="0 0 -1"/>
      <geom type="plane" size="2 2 0.1" rgba="1 1 1 1"/>
      <body pos="0 0 0.6" euler="0 0 90">
         <joint name="t0" type="hinge" axis="0 0 1" pos="0 0 0"/>
         <geom type="cylinder" size="0.05 0.5" rgba="0 0 1 1"/>
         <body>
            <joint name="t1" type="hinge" axis="-1 0 0" pos="0 0 0.5"/>
            <geom pos="0 0.5 0.5" euler="90 0 0" type="cylinder" size="0.05 0.5" rgba="1 0 0 1"/>
            <body>
               <joint name="t2" type="hinge" axis="-1 0 0" pos="0 1 0.5"/>
               <geom pos="0 1.5 0.5" euler="90 0 0" type="cylinder" size="0.05 0.5" rgba="0 1 0 1"/>
               <site name="tip" size="0.1" pos="0 2 0.5"/>
            </body>
         </body>
      </body>
   </worldbody>
   <sensor>
      <framepos objtype="site" objname="tip"/>
   </sensor>
   <actuator>
      <position name="theta_0" joint="t0"/>
      <position name="theta_1" joint="t1"/>
      <position name="theta_2" joint="t2"/>
   </actuator>
</mujoco>
