<mujoco>
  <compiler autolimits="true"/>

  <asset>
    <texture name="grid" type="2d" builtin="checker" width="512" height="512" rgb1=".1 .2 .3" rgb2=".2 .3 .4"/>
    <material name="grid" texture="grid" texrepeat="1 1" texuniform="true" reflectance=".2"/>
    <mesh name="chasis" scale=".01 .006 .0015" vertex=" 9   2   0
              -10  10  10
               9  -2   0
               10  3  -10
               10 -3  -10
              -8   10 -10
              -10 -10  10
              -8  -10 -10
              -5   0   20"/>
  </asset>

  <default>
    <joint damping=".03" actuatorfrcrange="-0.5 0.5"/>
    <default class="wheel">
      <geom type="cylinder" size=".03 .01" rgba=".5 .5 1 1"/>
    </default>
    <default class="decor">
      <site type="box" rgba=".5 1 .5 1"/>
    </default>
  </default>

  <worldbody>
    <light pos="1 0 3" dir="0 0 -1"/>
    <light pos="-1 0 3" dir="0 0 -1"/>
    <light pos="0 1 3" dir="0 0 -1"/>
    <light pos="0 -1 3" dir="0 0 -1"/>

    <geom type="plane" size="3 3 .01" material="grid"/>
    <!--<body name="target-ball" pos="0 0 .025">
      <inertial pos="0 0 0" mass="1" diaginertia="1 1 1"/>
      <geom type="sphere" size=".05" rgba="1 0 0 1" friction="0.6 0.3 10"/>
    </body>-->
    <body name="target-box" pos="0 0 .025">
      <inertial pos="0 0 0" mass="0.1" diaginertia="1 1 1"/>
      <geom type="box" size=".05 .05 .05" rgba="1 0 0 1"/>
      <joint name="target" type="free"/>
    </body>
    <body name="car 1" pos="0 1 .03">
      <freejoint/>
      <light name="top light 1" pos="0 0 2" mode="trackcom" diffuse=".4 .4 .4"/>
      <geom name="chasis 1" type="mesh" mesh="chasis"/>
      <geom name="front wheel 1" pos=".08 0 -.015" type="sphere" size=".015" condim="1" priority="1"/>
      <light name="front light 1" pos=".1 0 .02" dir="2 0 -1" diffuse="1 1 1"/>
      <body name="left wheel 1" pos="-.07 .06 0" zaxis="0 1 0">
        <joint name="left 1"/>
        <geom class="wheel"/>
        <site class="decor" size=".006 .025 .012"/>
        <site class="decor" size=".025 .006 .012"/>
      </body>
      <body name="right wheel 1" pos="-.07 -.06 0" zaxis="0 1 0">
        <joint name="right 1"/>
        <geom class="wheel"/>
        <site class="decor" size=".006 .025 .012"/>
        <site class="decor" size=".025 .006 .012"/>
      </body>
      <camera name="camera1" pos="-0.1 0 0.05" fovy="90" euler="180 -80 90"/>
    </body>
    <body name="car 2" pos="1 0 .03" euler="0 0 180">
      <freejoint/>
      <light name="top light 2" pos="0 0 2" mode="trackcom" diffuse=".4 .4 .4"/>
      <geom name="chasis 2" type="mesh" mesh="chasis"/>
      <geom name="front wheel 2" pos=".08 0 -.015" type="sphere" size=".015" condim="1" priority="1"/>
      <light name="front light 2" pos=".1 0 .02" dir="2 0 -1" diffuse="1 1 1"/>
      <body name="left wheel 2" pos="-.07 .06 0" zaxis="0 1 0">
        <joint name="left 2"/>
        <geom class="wheel"/>
        <site class="decor" size=".006 .025 .012"/>
        <site class="decor" size=".025 .006 .012"/>
      </body>
      <body name="right wheel 2" pos="-.07 -.06 0" zaxis="0 1 0">
        <joint name="right 2"/>
        <geom class="wheel"/>
        <site class="decor" size=".006 .025 .012"/>
        <site class="decor" size=".025 .006 .012"/>
      </body>
    </body>

  </worldbody>

  <tendon>
    <fixed name="forward 1">
      <joint joint="left 1" coef=".5"/>
      <joint joint="right 1" coef=".5"/>
    </fixed>
    <fixed name="turn 1">
      <joint joint="left 1" coef="-.5"/>
      <joint joint="right 1" coef=".5"/>
    </fixed>

    <fixed name="forward 2">
      <joint joint="left 2" coef=".5"/>
      <joint joint="right 2" coef=".5"/>
    </fixed>
    <fixed name="turn 2">
      <joint joint="left 2" coef="-.5"/>
      <joint joint="right 2" coef=".5"/>
    </fixed>
  </tendon>

  <actuator>
    <motor name="forward 1" tendon="forward 1" ctrlrange="-1 1"/>
    <motor name="turn 1" tendon="turn 1" ctrlrange="-1 1"/>

    <motor name="forward 2" tendon="forward 2" ctrlrange="-1 1"/>
    <motor name="turn 2" tendon="turn 2" ctrlrange="-1 1"/>
  </actuator>

  <sensor>
    <jointactuatorfrc name="right 1" joint="right 1"/>
    <jointactuatorfrc name="left 1" joint="left 1"/>

    <jointactuatorfrc name="right 2" joint="right 2"/>
    <jointactuatorfrc name="left 2" joint="left 2"/>
  </sensor>
</mujoco>
