<!-- Cartpole Model with Pole Control -->

<mujoco model='test_cartpole'>
  <compiler inertiafromgeom='true' coordinate='local'/>

  <option timestep='0.01'/>

  <worldbody>
    <light name='top' pos='0 0 1.5'/>
    <camera name='fixed' pos='0 -2.5 0' quat='0.707 0.707 0 0'/>
    <geom name='floor' pos='0 0 -1' size='4 4 4' type='plane' />
    <body name='cart' pos='0 0 0'>
      <joint name='slider' type='slide' limited='true' pos='0 0 0' axis='1 0 0' range='-5 5' />
      <geom name='cart' type='box' pos='0 0 0' size='0.2 0.1 0.05' rgba='0.7 0.7 0 1'/>
      <body name='pole' pos='0 0 0'>
        <camera name='pole' pos='0 -2.5 0' quat='0.707 0.707 0 0' />
        <joint name='hinge' type='hinge' pos='0 0 0' axis='0 1 0'/>
        <geom name='cpole' type='capsule' fromto='0 0 0 0 0 0.5' size='0.06 0.001' rgba='0 0.7 0.7 1'/>
      </body>
    </body>
  </worldbody>

  <actuator>
    <motor name='slide' joint='slider' gear='50' ctrllimited='true' ctrlrange='-1 1' />
  </actuator>

</mujoco>
